Workbook

Sheet  EQUIPOS 
A2: CONTROL DE LOS EQUIPOS DE MEDICIÓN
B4: DEPARTAMENTO / PROYECTO: | D4: PB ISA 2024-PA-215 "SERVICIO INTEGRAL DE MANTENIMIENTO PREDICTIVO, PREVENTIVO, CORRECTIVO Y OPERACIÓN DE LA PLANTA TERMOELECTRICA BAJO GRANDE"
J5: FECHA DE ACTUALIZACIÓN: | M5: =TODAY() -> 45864 | N5: HOY
A6: ÍTEM | B6: CÓDIGO INTERNO | C6: NOMBRE DEL EQUIPO | D6: SERIAL | E6: MARCA / MODELO | F6: RANGO/ CAPACIDAD | G6: UBICACIÓN | H6: FRECUENCIA DE CALIBRACIÓN, AJUSTE Y/O MANTENIMIENTO | I6: FECHA DE ÚLTIMA CALIBRACIÓN, AJUSTE Y/O MANTENIMIENTO | J6: FECHA DE PRÓXIMA CALIBRACIÓN, AJUSTE Y/O MANTENIMIENTO | K6: AGENTE CERTIFICADOR | L6: OBSERVACIONES
A7: EQUIPOS DE MEDICIÓN (Definir tipo: EQUIPOS MECÁNICOS (MEC), ELÉCTRICOS (ELEC), INSTRUMENTACIÓN (INT), SIA (S) )
A8: 1 | C8: Alineador Laser | D8: 43213804 | E8: DB pruftechnik | F8: 2mm | G8: PTBG | H8: ANUAL | I8: 45675 | J8: 46040 | M8: =J8-M$5 -> 176
A9: 2 | C9: BAKER B1600, Calibrador de presion. | D9: B09JPDP6K1 | E9: BAKER / B1600 | F9: 0 A 160 IN H2O | G9: PTBG | H9: ANUAL | I9: 45573 | J9: 45938 | M9: =J9-M$5 -> 74
A10: 3 | C10: Bomba para prueba hidraulica 0 A 10000 PSI | D10: 6559033MV | E10: FLUKE/ 700HTP-2 | F10: 0 A 10000 PSI T- 0 ⁰C A 50 ⁰C | G10: PTBG | H10: ANUAL | I10: 45747 | J10: 46112 | M10: =J10-M$5 -> 248
A11: 4 | C11: Bomba para prueba hidraulica | D11: 6920 | E11: FLUKE/ 700HTP-2 | F11: 0 A 10000 PSI T- 0 ⁰C A 50 ⁰C | G11: PTBG | H11: ANUAL | I11: 45736 | J11: 46101 | M11: =J11-M$5 -> 237
A12: 5 | C12: Bomba de comprobacion de baja presion (low pressure test pump) | D12: 6549329 | E12: FLUKE/ 700LTP1 | F12: 12,7 PSI A 100 PSI | G12: PTBG | H12: ANUAL | I12: 45736 | J12: 46101 | L12: INSTRUMENTO | M12: =J12-M$5 -> 237
A13: 6 | C13: Cable puesta a tierra temporaria con sus 3 conectores rigidos (mordaza) | D13: 61138 | E13: FAMECA/ C132-ISC35 | F13: 25 Ka/60 ciclos-35.5 kA/30 ciclos | G13: PTBG | H13: ANUAL | I13: 45704 | J13: 46069 | M13: =J13-M$5 -> 205
A14: 7 | C14: Calibrador de proceso de documentacion | D14: 9478031 | E14: FLUKE/ 744 | F14: N/A | G14: PTBG | H14: ANUAL | I14: 45682 | J14: 46047 | L14: INSTRUMENTO | M14: =J14-M$5 -> 183
A15: 8 | C15: Calibrador de Temperatura | D15: 40826 | E15: DRUCK LIMITED/ DBC650 | F15: (-45 HASTA650 ⁰C) | G15: PTBG | H15: ANUAL | I15: 45575 | J15: 45940 | M15: =J15-M$5 -> 76
A16: 9 | C16: Comunicador de campo | D16: 11099676 | E16: EMERSON/ 475 | F16: 0-100% | G16: PTBG | H16: ANUAL | I16: 45574 | J16: 45939 | M16: =J16-M$5 -> 75
A17: 10 | C17: Comunicador de campo | D17: 4540536 | E17: FLUKE/ 709H | F17: 0-100% | G17: PTBG | H17: ANUAL | I17: 45574 | J17: 45939 | M17: =J17-M$5 -> 75
A18: 11 | C18: Detector de gas SF6 | D18: 4199 | E18: DILO ARMATUREN/ 3-033-R002 | F18: INDICADOR POR COLORES | G18: PTBG | H18: ANUAL | I18: 45643 | J18: 46008 | M18: =J18-M$5 -> 144
A19: 12 | C19: Detector de Alta Tension (Voltimetro) | D19: 2160194 | E19: JGW / 277HP | F19: 50V Hasta 132 KVAC | G19: PTBG | H19: ANUAL | I19: 45706 | J19: 46071 | M19: =J19-M$5 -> 207
A20: 13 | C20: Detector Multigas. (COMB/EX-CO-H2S, 02) | D20: ARXM-0500 | E20: DRAGER / X-AM3000 | F20: _________ | G20: PTBG | H20: SEMESTRAL | I20: 45573 | J20: 45755 | L20: NO APTO | M20: =J20-M$5 -> -109
A21: 14 | C21: Detector Multigas. (COMB/EX-CO-H2S, 02) | D21: N20230820382 | E21: CHNADKS/ X-4 | F21: _________ | G21: PTBG | H21: SEMESTRAL | I21: 45755 | J21: 45938 | M21: =J21-M$5 -> 74
A22: 15 | C22: Druck PV 211 | D22: OO5140 | E22: GE/ PV211 | F22: 0 A 600 PSI T- 0 ⁰C A 50 ⁰C | G22: PTBG | H22: ANUAL | I22: 45736 | J22: 46101 | M22: =J22-M$5 -> 237
A23: 16 | C23: DTX-1800 (Voltimetro) | D23: 1813069/ 1813070 | E23: FLUKE/ DTX 1800 | F23: Según escala | G23: PTBG | H23: ANUAL | I23: 45506 | J23: 45871 | M23: =J23-M$5 -> 7
A24: 17 | C24: DTX-1800 (Voltimetro) | D24: 1665023 | E24: FLUKE/ DTX-MFM2 | F24: Según escala | G24: PTBG | H24: ANUAL | I24: 45506 | J24: 45871 | M24: =J24-M$5 -> 7
A25: 18 | C25: DTX-1800 (Voltimetro) | D25: 1855623 | E25: FLUKE/ DTX-MFM2 | F25: Según escala | G25: PTBG | H25: ANUAL | I25: 45506 | J25: 45871 | M25: =J25-M$5 -> 7
A26: 19 | C26: DTX-1800 (Voltimetro) | D26: 1855616 | E26: FLUKE/ DTX-MFM2 | F26: Según escala | G26: PTBG | H26: ANUAL | I26: 45506 | J26: 45871 | M26: =J26-M$5 -> 7
A27: 20 | C27: DTX-1800 (Voltimetro) | D27: 9670008 | E27: FLUKE/ DTX-MFM2 | F27: Según escala | G27: PTBG | H27: ANUAL | I27: 45506 | J27: 45871 | M27: =J27-M$5 -> 7
A28: 21 | C28: Guante de goma para baja tension | D28: 4095607 A | E28: SALISBURY/ CLASE 0 TIPO1 | F28: 1000 V | G28: PTBG | H28: SEMESTRAL | I28: 45695 | J28: 45876 | K28: CORPOELEC | L28: PCM2 | M28: =J28-M$5 -> 12
A29: 22 | C29: Guante de goma para baja tension | D29: 409560 B | E29: SALISBURY/ CLASE 0 TIPO1 | F29: 1000 V | G29: PTBG | H29: SEMESTRAL | I29: 45695 | J29: 45876 | K29: CORPOELEC | M29: =J29-M$5 -> 12
A30: 23 | C30: Guante de goma para baja tension | D30: 4122575 | E30: SALISBURY/ CLASE 0 TIPO1 | F30: 1000 V | G30: PTBG | H30: SEMESTRAL | I30: 45695 | J30: 45876 | K30: CORPOELEC | M30: =J30-M$5 -> 12
A31: 24 | C31: Guante de goma para baja tension | D31: 4096511 | E31: SALISBURY/ CLASE 0 TIPO1 | F31: 1000 V | G31: PTBG | H31: SEMESTRAL | I31: 45695 | J31: 45876 | K31: CORPOELEC | L31: PCM 1 | M31: =J31-M$5 -> 12
A32: 25 | C32: Guante Dielectrico , CLASE 2 TIPO 1 | D32: C2S10 G0021F | E32: MARIGOLD/ EN60903 | F32: 17000 V AC MAX | G32: PTBG SALA DE CONTROL | H32: SEMESTRAL | I32: 45746 | J32: 45930 | K32: CORPOELEC | M32: =J32-M$5 -> 66
A33: 26 | C33: Guante Dielectrico , CLASE 4 TIPO 1 | D33: 3102632 | E33: SALISBURY/ D120 | F33: 36000 V AC | G33: PTBG SALA DE CONTROL | H33: SEMESTRAL | I33: 45565 | J33: 45930 | K33: CORPOELEC | M33: =J33-M$5 -> 66
A34: 27 | C34: Guante Dielectrico , CLASE 3 TIPO 1 de 12" | D34: 5332860 / 5332859 | E34: SALISBURY/ PRODUSCA D120/ ILP14 | F34: 26500 V AC | G34: PTBG | H34: SEMESTRAL | I34: 45613 | J34: 45794 | K34: CORPOELEC | M34: =J34-M$5 -> -70
A35: 28 | C35: Guante Dielectrico , CLASE 0 TIPO 1 | D35: 4122176 | E35: SALISBURY / D120 TIPO 1 | F35: 1000 V AC MAX | G35: PTBG | H35: SEMESTRAL | I35: 45695 | J35: 45876 | K35: CORPOELEC | M35: =J35-M$5 -> 12
A36: 29 | B36: SF-HM-001 | C36: HM-BLE, modem HART de baja energia bluetooth | D36: 1230155 | E36: PROCOMSOL/ HM-BLE | F36: Según escala | G36: PTBG | H36: ANUAL | I36: 45619 | J36: 45984 | L36: INSTRUMENTO | M36: =J36-M$5 -> 120
A37: 30 | C37: Maquina de Soldar Electrica | D37: 12C9K419400100391480056 | E37: HOFFMAMART /LASSEN 200 | F37: 0 -200 A | G37: PTBG | H37: SEMESTRAL | I37: 45327 | J37: 45874 | K37: INTEST, C.A | M37: =J37-M$5 -> 10
A38: 31 | C38: Maquina de Soldar | D38: U1080600539 | E38: LINCOLN/ VANTAGE. K2405-2 | F38: 0-500 A | G38: PTBG | H38: SEMESTRAL | I38: 45327 | J38: 45874 | K38: INTEST, C.A | M38: =J38-M$5 -> 10
A39: 32 | C39: Manometro 0-3000 psi | D39: 6185365 | E39: FLUKE / 700RG29 3K | F39: 0-3000 PSI | G39: PTBG | H39: ANUAL | I39: 45682 | J39: 46047 | L39: INSTRUMENTO | M39: =J39-M$5 -> 183
A40: 33 | C40: Megger | D40: 110870SADV | E40: MEGOHMETRO/ AEMC 6505 | F40: 0 A 5 KV | G40: PTBG | H40: ANUAL | I40: 45574 | J40: 45939 | M40: =J40-M$5 -> 75
A41: 34 | C41: Modulo de presion 750PDS 0 A 100 PSI | D41: 3212012 | E41: FLUKE/ 750PD5 | F41: 15/30PSIG | G41: PTBG | H41: ANUAL | I41: 45747 | J41: 46112 | M41: =J41-M$5 -> 248
A42: 35 | C42: Modulo de presion 750PD5 0 A 5000 PSI | D42: 6269278 | E42: FLUKE/ 750PD5 | F42: 15/30PSIG | G42: PTBG | H42: ANUAL | I42: 45747 | J42: 46112 | M42: =J42-M$5 -> 248
...

Sheet HERRAMIENTAS
A2: CONTROL DE LOS EQUIPOS DE MEDICIÓN
B4: DEPARTAMENTO / PROYECTO: | D4: PB ISA 2024-PA-215 "SERVICIO INTEGRAL DE MANTENIMIENTO PREDICTIVO, PREVENTIVO, CORRECTIVO Y OPERACIÓN DE LA PLANTA TERMOELECTRICA BAJO GRANDE"
J5: FECHA DE ACTUALIZACIÓN: | M5: =TODAY() -> 45864 | N5: HOY
A6: ÍTEM | B6: CÓDIGO INTERNO | C6: NOMBRE DEL EQUIPO | D6: SERIAL | E6: MARCA / MODELO | F6: RANGO/ CAPACIDAD | G6: UBICACIÓN | H6: FRECUENCIA DE CALIBRACIÓN, AJUSTE Y/O MANTENIMIENTO | I6: FECHA DE ÚLTIMA CALIBRACIÓN, AJUSTE Y/O MANTENIMIENTO | J6: FECHA DE PRÓXIMA CALIBRACIÓN, AJUSTE Y/O MANTENIMIENTO | K6: AGENTE CERTIFICADOR | L6: OBSERVACIONES
A7: EQUIPOS DE MEDICIÓN (Definir tipo: HERRAMIENTAS MECÁNICOS: (MEC), ELÉCTRICOS (ELEC), INSTRUMENTACIÓN (INT), SIA (S) )
A8: 1 | B8: SF-AR-001 | C8: Arnes y Cabo de Vida | D8: 1909200025/EN3612002/ 0321 | E8: VAULTEX | F8: 140 KG | G8: PTBG | H8: ANUAL | I8: 45693 | J8: 46058 | K8: INTEST, C.A | L8: NO APTO | M8: =J8-M$5 -> 194
A9: 2 | B9: SF-AR-002 | C9: Arnes y Cabo de Vida | D9: 1909200025/EN3612002/ 0321 | E9: VAULTEX | F9: 140 KG | G9: PTBG | H9: ANUAL | I9: 45693 | J9: 46058 | K9: INTEST, C.A | M9: =J9-M$5 -> 194
A10: 3 | B10: SF-AR-005/006/007 | C10: Arnes y Cabo de Vida | D10: 1909200025/EN3612002/ 0321/190920040 | E10: VAULTEX /JOHA | F10: 200 KG | G10: PTBG | H10: ANUAL | I10: 45572 | J10: 45937 | K10: INTEST, C.A | L10: NO APTO CABO DE VIDA 005-007 | M10: =J10-M$5 -> 73
A11: 4 | B11: SF-AR-003/004 | C11: Arnes y Cabo de Vida | D11: 1909200025/EN3612002/ 0321 | E11: VAULTEX | F11: 310 KG | G11: PTBG | H11: ANUAL | I11: 45735 | J11: 46100 | K11: INTEST, C.A | M11: =J11-M$5 -> 236
A12: 5 | B12: SF-AR-008/009/010/011 | C12: Arnes y Cabo de Vida | D12: 202408 19092000200 | E12: VAULTEX | F12: 310 KG | G12: PTBG 10 y 11 (refineria) | H12: ANUAL | I12: 45619 | J12: 45984 | K12: INTEST, C.A | M12: =J12-M$5 -> 120
A13: 6 | B13: SF-AR-012/013/014/015/016/017/108 | C13: Arnes y Cabo de Vida | D13: FA30401 FA30401 0472 0351 0259 0436 0472 | E13: INTOOL PALOMA | F13: 140 KG | G13: PTBG | H13: ANUAL | I13: 45746 | J13: 46111 | L13: AMARILLOS CON NEGRO | M13: =J13-M$5 -> 247
A14: 7 | C14: Cable de acero 1´´ X 3 Mts | D14: K16-P324 | E14: _________ | F14: 7.7 t Lazo 5,7 t canasta: 15,4t | G14: PTBG | H14: ANUAL | I14: 45395 | J14: 45760 | L14: NO CERTIFICAR | M14: =J14-M$5 -> -104
A15: 8 | C15: Aparejos de izamiento (Cancamos) | D15: C-15 (7 UND) C-25 (2UND) C-15 (4 UND) | E15: WSLL | F15: 5200 LB 13300 LB 10600 LB | G15: PTBG | H15: ANUAL | I15: 45760 | J15: 46125 | K15: INTEST, C.A | M15: =J15-M$5 -> 261
A16: 9 | C16: Aparejos de izamiento (Cancamos) Bg-2 | D16: C-1 / C-2/C-3/C-4/C-5/C-6/C-7/C-8/C-9/C-10/C-11/C-12/C-13 | E16: WSLL 14mm 19mm | F16: 2000 Kg 2400 Kg 5000 Kg | G16: PTBG | H16: ANUAL | I16: 45728 | J16: 46093 | K16: INVERMULCA | M16: =J16-M$5 -> 229
A17: 10 | C17: Aparejos de izamiento (Cancamos) Bg-1 | D17: C-14/C-15/C-16 | E17: WSLL 14mm 19mm | F17: 3000 Kg 2000 Kg | G17: PTBG | H17: ANUAL | I17: 45728 | J17: 46093 | K17: INVERMULCA | M17: =J17-M$5 -> 229
A18: 11 | C18: Eslinga modelo 11 de 25.40 mm: 1´x 300 mts de cable de acero AM AA ARD 180 | D18: 050400055A | E18: BOA | F18: 41.700 KG | G18: PTBG | H18: ANUAL | I18: 45629 | J18: 45994 | K18: INTEST, C.A | M18: =J18-M$5 -> 130
A19: 12 | C19: Eslinga modelo 11: Cable de acero 3/4" X 3´ | D19: 050400035A 2 Und | E19: __________ | F19: VERTICAL: 4.448 Kg LAZO: 3.268 Kg CESTA:8.806 Kg | G19: PTBG | H19: ANUAL | I19: 45770 | J19: 46135 | M19: =J19-M$5 -> 271
A20: 13 | C20: Eslinga de 2¨x2 mts/ 3¨x1mts/ 3¨x2 mts/3¨x3 mts / 4¨x 3 mts Protector para eslinga de 3¨ | D20: EC2B-2B/ EC3B-1B /EC3B-2B/ EC3B-3B /EC4B-3B | E20: _________ | F20: VERTICAL: 2000 CESTA:4000 Kg | G20: PTBG | H20: ANUAL | I20: 45693 | J20: 46058 | K20: INTEST, C.A | M20: =J20-M$5 -> 194
A21: 14 | B21: EC1B-1B | C21: Eslinga de izamiento de carga 1¨x 1 mts Naranja | D21: 092503/ 092504/ 092505/ 092506 | F21: Kg.U 2000 Kg Kg.Vertical 1000Kg Kg.Lazo 8.00 Kg | G21: PTBG | H21: ANUAL | I21: 45715 | J21: 46080 | M21: =J21-M$5 -> 216
A22: 15 | B22: EC2B-2B | C22: Eslinga de izamiento de carga 2¨x 2 mts Naranja | D22: 092507/ 092508/ 092509/ 092510 | F22: Kg.U 4000 Kg Kg.Vertical 2000Kg Kg.Lazo 1.600 Kg | G22: PTBG | H22: ANUAL | I22: 45715 | J22: 46080 | M22: =J22-M$5 -> 216
A23: 16 | B23: EP3B-1 | C23: Eslinga de izamiento de carga 3.5¨x 1 mts Amarillo | D23: 92512 | F23: Kg.U 8.400 Kg Kg.Vertical 4.200Kg Kg.Lazo 3.360 Kg | G23: PTBG | H23: ANUAL | I23: 45715 | J23: 46080 | M23: =J23-M$5 -> 216
A24: 17 | B24: EP3B-2 | C24: Eslinga de izamiento de carga 3.5¨x 2 mts Amarillo | D24: 452408 | F24: Kg.U 8.400 Kg Kg.Vertical 4.200Kg Kg.Lazo 3.360 Kg | G24: PTBG | H24: ANUAL | I24: 45715 | J24: 46080 | M24: =J24-M$5 -> 216
A25: 18 | B25: EC1B-1B EC2B-2B | C25: Eslinga de 1¨x1mts / 2¨x2mts (Naranja) | D25: 162426/ 162427/ 162428/ 162429/ 112417/ 112418/ 142409/ 142410 | E25: _________ | F25: 1¨2000 Kg 2¨4000 Kg | G25: PTBG | H25: ANUAL | I25: 45399 | J25: 45764 | K25: INTEST, C.A | L25: NO APTO | M25: =J25-M$5 -> -100
A26: 19 | B26: EP3B-3 EP3B-1 | C26: Eslinga poliester alta tenacidad (Amarrillo) 9cmx 3mts 9cm x 1mts | D26: 162418/ 162419/ 162420/ 162421/ 162422/ 162423/ 162424/ 162425 | E26: _________ | F26: 6000 Kg a 8400 Kg | G26: PTBG | H26: ANUAL | I26: 45764 | J26: 46129 | K26: INTEST, C.A | M26: =J26-M$5 -> 265
A27: 20 | B27: EP3B-3 EP3B-3 | C27: Eslinga de izamiento 3.5¨ (9cm) Amarillo | D27: 222404/222405/ 412407/412408 | E27: _________ | F27: 2400 kg a 8400 kg | G27: PTBG | H27: ANUAL | I27: 45610 | J27: 45975 | K27: INTEST, C.A | M27: =J27-M$5 -> 111
A28: 21 | B28: EC2B-2B EC2B-2B | C28: Eslinga de izamiento 2" (2m) Naranja | D28: 092511 / 142414 | E28: ESLINCARGA | F28: "U" 4000 Kg "V" 2000 Kg "Lazo" 1600 Kg | G28: PTBG | H28: ANUAL | I28: 45779 | J28: 46144 | M28: =J28-M$5 -> 280
A29: 22 | B29: EC1B-1B | C29: Eslinga de izamiento 1¨X1 mts Naranja | D29: 482438 | E29: ESLINCARGA | F29: 800 kg a 2000 kg | G29: PTBG | H29: ANUAL | I29: 45628 | J29: 45993 | K29: INTEST, C.A | M29: =J29-M$5 -> 129
A30: 23 | B30: EC2B | C30: Eslinga de izamiento 2¨ X 2mts Naranja | D30: 382403 | E30: ESLINCARGA | F30: 1600 kg A 4000 kg | G30: PTBG | H30: ANUAL | I30: 45629 | J30: 45994 | K30: INTEST, C.A | L30: NO APTO | M30: =J30-M$5 -> 130
A31: 24 | C31: Grilletes | D31: Pintado por el extremo de color verde | E31: TAIYO/WLL DT7M | F31: 4-5 A 8 T | G31: PTBG | H31: ANUAL | I31: 45593 | J31: 45958 | K31: INTEST, C.A | M31: =J31-M$5 -> 94
A32: 25 | C32: Grilletes | D32: G-A/ G-B/G-C/G-D/M-A (4 Und)/ E-A (4 Und)/ F-A (4Und) | E32: CHICAGO | F32: 1T A 6 ½ ˝ | G32: PTBG | H32: ANUAL | I32: 45767 | J32: 46132 | K32: INTEST, C.A | M32: =J32-M$5 -> 268
A33: 26 | C33: Grilletes | D33: E-A (4 UND) | E33: CAMPBELL/ WLL | F33: Tamaño: 5/8´ Capacidad:3.1/4´ | G33: PTBG | H33: ANUAL | I33: 45771 | J33: 46136 | M33: =J33-M$5 -> 272
C34: Grilletes | D34: E-A (4 UND) | E34: CAMPBELL/ WLL | F34: Tamaño: 5/8´ Capacidad:3.1/4´ | G34: PTBG | H34: ANUAL | I34: 45777 | J34: 46142 | M34: =J34-M$5 -> 278
A35: 27 | C35: Soporte ajustable para 7 T | D35: _________ | E35: TIPO AJUSTABLE | F35: 7 T | G35: PTBG | H35: ANUAL | I35: 45227 | J35: 45593 | M35: =J35-M$5 -> -271
A36: 28 | C36: Soporte fijo para 7 T | D36: _________ | E36: TIPO FIJO | F36: 7 T | G36: PTBG | H36: ANUAL | I36: 45227 | J36: 45593 | M36: =J36-M$5 -> -271
A37: 29 | B37: SF-AR-019 | C37: ARNES Y CABO DE VIDA | D37: 19092000250 | E37: VAULTEX/ PSH022 VAULTEX/ VT-6709 | F37: 310 LBS | G37: PTBG | H37: ANUAL | I37: 45788 | J37: 46153 | K37: INTEST, C.A | M37: =J37-M$5 -> 289
A38: 30 | B38: SF-AR-020 | C38: ARNES Y CABO DE VIDA | D38: 19092000250 | E38: VAULTEX/ PSH022 VAULTEX/ VT-6709 | F38: 310 LBS | G38: PTBG | H38: ANUAL | I38: 45788 | J38: 46153 | K38: INTEST, C.A | M38: =J38-M$5 -> 289
A39: 31 | B39: SF-AR-021 | C39: ARNES Y CABO DE VIDA | D39: 19092000250 | E39: VAULTEX/ PSH022 VAULTEX/ VT-6709 | F39: 310 LBS | G39: PTBG | H39: ANUAL | I39: 45788 | J39: 46153 | K39: INTEST, C.A | M39: =J39-M$5 -> 289
A40: 32 | M40: =J40-M$5 -> -45864
A41: 33 | M41: =J41-M$5 -> -45864
A42: 34 | M42: =J42-M$5 -> -45864
...

Sheet  MAQUINARIA PESADA
A2: CONTROL DE LOS EQUIPOS DE MEDICIÓN
B4: DEPARTAMENTO / PROYECTO: | D4: PB ISA 2024-PA-215 "SERVICIO INTEGRAL DE MANTENIMIENTO PREDICTIVO, PREVENTIVO, CORRECTIVO Y OPERACIÓN DE LA PLANTA TERMOELECTRICA BAJO GRANDE"
J5: FECHA DE ACTUALIZACIÓN: | M5: =TODAY() -> 45864 | N5: HOY
A6: ÍTEM | B6: CÓDIGO INTERNO | C6: NOMBRE DEL EQUIPO | D6: SERIAL | E6: MARCA / MODELO | F6: RANGO/ CAPACIDAD | G6: UBICACIÓN | H6: FRECUENCIA DE CALIBRACIÓN, AJUSTE Y/O MANTENIMIENTO | I6: FECHA DE ÚLTIMA CALIBRACIÓN, AJUSTE Y/O MANTENIMIENTO | J6: FECHA DE PRÓXIMA CALIBRACIÓN, AJUSTE Y/O MANTENIMIENTO | K6: AGENTE CERTIFICADOR | L6: OBSERVACIONES
A7: VEHICULOS Y MAQUINARIA PESADA
A8: 1 | C8: Batea de 3 eje | D8: 10081431 | E8: Free Ways/ SPT | F8: 32 Ton | G8: BOSCAN | H8: ANUAL | I8: 45569 | J8: 45934 | M8: =J8-M$5 -> 70
A9: 2 | C9: Brazo Articulado | D9: 3641 | E9: Toyota /P 5000L | F9: 2.2 Ton | G9: PTBG | H9: ANUAL | I9: 45544 | J9: 45909 | M9: =J9-M$5 -> 45
A10: 3 | B10: PTBGD-02 | C10: Cuna de Turbina | D10: ______ | E10: DOLLYN | F10: 4500 KG | G10: PTBG | H10: ANUAL | I10: 45771 | J10: 46136
A11: 4 | B11: GPD1A | C11: Grua Monoriel | D11: 10010267 | E11: Toyo chain block / GCT610-3-ST | F11: 3T | G11: PTBG | H11: ANUAL | I11: 45715 | J11: 46080 | L11: CENTRIFUGADORA | M11: =J11-M$5 -> 216
A12: 5 | B12: GPD1B | C12: Grua Monoriel | D12: 10010267 | E12: Toyo chain block / GCT610-3-ST | F12: 3T | G12: PTBG | H12: ANUAL | I12: 45715 | J12: 46080 | L12: CENTRIFUGADORA | M12: =J12-M$5 -> 216
A13: 6 | B13: GPD1C | C13: Grua Monoriel | D13: 10010267 | E13: Toyo chain block / GCT610-3-ST | F13: 3T | G13: PTBG | H13: ANUAL | I13: 45715 | J13: 46080 | L13: CENTRIFUGADORA | M13: =J13-M$5 -> 216
A14: 7 | C14: Grua Monoriel | D14: 189083189 | E14: CHESTER / ZEPHYR | F14: 10.000 KGS | G14: PTBG | H14: ANUAL | I14: 45378 | J14: 45743 | L14: BG-1 | M14: =J14-M$5 -> -121
A15: 8 | C15: Grua Monoriel | D15: ZLG-6143 | E15: CHESTER / ZEPHYR | F15: 10.000 KGS | G15: PTBG | H15: ANUAL | I15: 45630 | J15: 45995 | L15: BG-2 | M15: =J15-M$5 -> 131
A16: 9 | C16: Grua Puente | D16: 261-3310 | E16: TIGER | F16: 3T | G16: PTBG | H16: ANUAL | I16: 45767 | J16: 46132 | L16: Area comun (resguardado en almacen ) | M16: =J16-M$5 -> 268
A17: 10 | C17: Grua Puente | D17: HLW24648 | E17: R&M /SX30410032P25FALOF | F17: 3.200 KGS | G17: PTBG | H17: ANUAL | I17: 45547 | J17: 45912 | L17: TALLER ELECTRICO | M17: =J17-M$5 -> 48
A18: 11 | C18: Grua Puente | D18: HLW25869 | E18: R&M /SX50610150P55FDNOF | F18: 15.000 KGS | G18: PTBG | H18: ANUAL | I18: 45547 | J18: 45912 | L18: TALLER MECANICO | M18: =J18-M$5 -> 48
A19: 12 | C19: Grua sobre Camion Comercial | D19: 2664 | E19: FERRARI / IBP 30500XL/4SI | F19: 13.500 KGS | G19: PTBG | H19: ANUAL | I19: 45544 | J19: 45909 | M19: =J19-M$5 -> 45
A20: 13 | B20: S-LF-01 | C20: Lift Fixture (accesorio de ascensor) | D20: 288870-C | E20: LM6000 / TIPO AVION | F20: Capacidad Nominal: 9.299 Kg Capacidad Seguro: 7439 Kg | G20: PTBG | H20: ANUAL | I20: 45779 | J20: 46144 | M20: =J20-M$5 -> 280
A21: 14 | B21: SML-401 | C21: Manlift | D21: 021014-0300022330 | E21: JLG/ 60H | F21: 450 KG | G21: PTBG | H21: ANUAL | I21: 45598 | J21: 45963 | M21: =J21-M$5 -> 99
A22: 15 | B22: SML-400 | C22: Montacarga | D22: CGP460G-0887-9450FB | E22: CLARK/ CGP50 | F22: 4 T | G22: PTBG | H22: ANUAL | I22: 45476 | J22: 45841 | M22: =J22-M$5 -> -23
A23: 16 | B23: S-163 | C23: Quinta Rueda | D23: C06004862T | E23: HOLLAND/FREIGHTLINER | F23: 46 Ton | G23: Zona Industrial | H23: ANUAL | I23: 45561 | J23: 45926 | M23: =J23-M$5 -> 62
A24: 17 | B24: SM-146 | C24: Retro Excavadora | D24: T03105J154735 | E24: JOHN DEERE/ 310SJ | F24: 10000 KG | G24: PTBG | H24: ANUAL | I24: 45597 | J24: 45962 | M24: =J24-M$5 -> 98
A25: 18 | C25: Valvula de seguridad | D25: T-09-25172 | E25: CROSBY/ 81PS1F68-8 | M25: =J25-M$5 -> -45864
A26: 19 | M26: =J26-M$5 -> -45864
A27: 20 | M27: =J27-M$5 -> -45864
A28: 21 | M28: =J28-M$5 -> -45864
A29: 22 | M29: =J29-M$5 -> -45864
A30: 23 | M30: =J30-M$5 -> -45864
A31: 24 | M31: =J31-M$5 -> -45864
A32: 25 | M32: =J32-M$5 -> -45864
A33: 26 | M33: =J33-M$5 -> -45864
A34: 27 | M34: =J34-M$5 -> -45864
A35: 28 | M35: =J35-M$5 -> -45864
A36: 29 | M36: =J36-M$5 -> -45864
A37: 30 | M37: =J37-M$5 -> -45864
... A61: 54 | M61: =J61-M$5 -> -45864
M62: =J62-M$5 -> -45864
M63: =J63-M$5 -> -45864
M64: =J64-M$5 -> -45864
M65: =J65-M$5 -> -45864

Sheet  EXTINTORES
A2: CONTROL DE LOS EQUIPOS DE MEDICIÓN
B4: DEPARTAMENTO / PROYECTO: | D4: PB ISA 2024-PA-215 "SERVICIO INTEGRAL DE MANTENIMIENTO PREDICTIVO, PREVENTIVO, CORRECTIVO Y OPERACIÓN DE LA PLANTA TERMOELECTRICA BAJO GRANDE"
J5: FECHA DE ACTUALIZACIÓN: | L5: =TODAY() -> 45864 | M5: HOY
A6: ÍTEM | B6: CÓDIGO INTERNO (ETIQUETA DE INSPECCION) | C6: NOMBRE DEL EQUIPO | D6: SERIAL | E6: TIPO U/O AGENTE | F6: CAPACIDAD | G6: UBICACIÓN | H6: FRECUENCIA DE MANTENIMIENTO/ RECARGA | I6: FECHA DE ÚLTIMA RECARGA Y/O MANTENIMIENTO | J6: FECHA DE PRÓXIMA RECARGA Y/O MANTENIMIENTO | K6: OBSERVACIONES
A7: EXTINTORES. (Nota: Todos se recargan Anualmente)
A8: 1 | C8: Extintor de Dioxido de Carbono | D8: 271515D | E8: Dioxido de Carbono | F8: 15 LBS | G8: PTBG | H8: QUINQUENAL | K8: Prueba Hidrostatica 24/8/2023 HASTA 24/8/2028 | L8: =J8-L$5 -> -45864
A9: 2 | B9: 13146 | C9: Extintor | D9: V.645457 | E9: CO2 | F9: 15 LBS | G9: PTBG | H9: ANUAL | I9: 45717 | J9: 46082 | K9: Prueba Hidrostatica 01/5/2021 HASTA 01/5/2026 | L9: =J9-L$5 -> 218
A10: 3 | B10: 13147 | C10: Extintor | D10: V.647904 | E10: CO2 | F10: 15 LBS | G10: PTBG | H10: ANUAL | I10: 45717 | J10: 46082 | K10: Prueba Hidrostatica 01/2/2023 HASTA 01/02/2028 | L10: =J10-L$5 -> 218
A11: 4 | B11: 13148 | C11: Extintor | D11: V.652314 | E11: CO2 | F11: 15 LBS | G11: PTBG | H11: ANUAL | I11: 45717 | J11: 46082 | K11: Prueba Hidrostatica 01/2/2023 HASTA 01/02/2028 | L11: =J11-L$5 -> 218
A12: 5 | B12: 13149 | C12: Extintor | D12: V.729174 | E12: CO2 | F12: 15 LBS | G12: PTBG | H12: ANUAL | I12: 45717 | J12: 46082 | K12: Prueba Hidrostatica 01/2/2023 HASTA 01/02/2028 | L12: =J12-L$5 -> 218
A13: 6 | B13: 13152 | C13: Extintor | D13: V.21562 | E13: CO2 | F13: 15 LBS | G13: PTBG | H13: ANUAL | I13: 45717 | J13: 46082 | K13: Prueba Hidrostatica 01/4/2021 HASTA 01/04/2026 | L13: =J13-L$5 -> 218
A14: 7 | B14: 16233 | C14: Extintor | D14: V.679975 | E14: CO2 | F14: 15 LBS | G14: PTBG | H14: ANUAL | I14: 45717 | J14: 46082 | K14: Prueba Hidrostatica 01/2/2023 HASTA 01/02/2028 | L14: =J14-L$5 -> 218
A15: 8 | B15: 16234 | C15: Extintor | D15: V.546190 | E15: CO2 | F15: 15 LBS | G15: PTBG | H15: ANUAL | I15: 45717 | J15: 46082 | K15: Prueba Hidrostatica 01/5/2021 HASTA 01/05/2026 | L15: =J15-L$5 -> 218
A16: 9 | B16: 16235 | C16: Extintor | D16: V.645592 | E16: CO2 | F16: 15 LBS | G16: PTBG | H16: ANUAL | I16: 45717 | J16: 46082 | K16: Prueba Hidrostatica 01/4/2024 HASTA 01/04/2029 | L16: =J16-L$5 -> 218
A17: 10 | B17: 16236 | C17: Extintor | D17: V.645487 | E17: CO2 | F17: 15 LBS | G17: PTBG | H17: ANUAL | I17: 45717 | J17: 46082 | K17: Prueba Hidrostatica 01/2/2021 HASTA 01/02/2030 | L17: =J17-L$5 -> 218
A18: 11 | B18: 16237 | C18: Extintor | D18: V-729195 | E18: CO2 | F18: 15 LBS | G18: PTBG | H18: ANUAL | I18: 45717 | J18: 46082 | K18: Prueba Hidrostatica 01/2/2023 HASTA 01/02/2028 | L18: =J18-L$5 -> 218
A19: 12 | B19: 16238 | C19: Extintor | D19: V-729183 | E19: CO2 | F19: 15 LBS | G19: PTBG | H19: ANUAL | I19: 45717 | J19: 46082 | K19: Prueba Hidrostatica 01/2/2023 HASTA 01/02/2028 | L19: =J19-L$5 -> 218
A20: 13 | B20: 13150 | C20: Extintor | D20: S/N | E20: PQS | F20: 20 LBS | G20: PTBG | H20: ANUAL | I20: 45717 | J20: 46082 | L20: =J20-L$5 -> 218
A21: 14 | B21: 13151 | C21: Extintor | D21: S/N | E21: PQS | F21: 20 LBS | G21: PTBG | H21: ANUAL | I21: 45717 | J21: 46082 | L21: =J21-L$5 -> 218
A22: 15 | B22: 13153 | C22: Extintor | D22: S/N | E22: PQS | F22: 20 LBS | G22: PTBG | H22: ANUAL | I22: 45717 | J22: 46082 | L22: =J22-L$5 -> 218
A23: 16 | B23: 13154 | C23: Extintor | D23: S/N | E23: PQS | F23: 20 LBS | G23: PTBG | H23: ANUAL | I23: 45717 | J23: 46082 | L23: =J23-L$5 -> 218
A24: 17 | B24: 13155 | C24: Extintor | D24: S/N | E24: PQS | F24: 20 LBS | G24: PTBG | H24: ANUAL | I24: 45717 | J24: 46082 | L24: =J24-L$5 -> 218
A25: 18 | B25: 13156 | C25: Extintor | D25: S/N | E25: PQS | F25: 20 LBS | G25: PTBG | H25: ANUAL | I25: 45717 | J25: 46082 | L25: =J25-L$5 -> 218
A26: 19 | B26: 13157 | C26: Extintor | D26: S/N | E26: PQS | F26: 20 LBS | G26: PTBG | H26: ANUAL | I26: 45717 | J26: 46082 | L26: =J26-L$5 -> 218
A27: 20 | B27: 13158 | C27: Extintor | D27: S/N | E27: PQS | F27: 20 LBS | G27: PTBG | H27: ANUAL | I27: 45717 | J27: 46082 | L27: =J27-L$5 -> 218
A28: 21 | B28: 13159 | C28: Extintor | D28: S/N | E28: PQS | F28: 20 LBS | G28: PTBG | H28: ANUAL | I28: 45717 | J28: 46082 | L28: =J28-L$5 -> 218
A29: 22 | B29: 16209 | C29: Extintor | D29: S/N | E29: PQS | F29: 20 LBS | G29: PTBG | H29: ANUAL | I29: 45717 | J29: 46082 | L29: =J29-L$5 -> 218
A30: 23 | B30: 16212 | C30: Extintor | D30: S/N | E30: PQS | F30: 20 LBS | G30: PTBG | H30: ANUAL | I30: 45717 | J30: 46082 | L30: =J30-L$5 -> 218
A31: 24 | B31: 16213 | C31: Extintor | D31: S/N | E31: PQS | F31: 20 LBS | G31: PTBG | H31: ANUAL | I31: 45717 | J31: 46082 | L31: =J31-L$5 -> 218
... A35: 28 | B35: 16217 | C35: Extintor | D35: S/N | E35: PQS | F35: 20 LBS | G35: PTBG | H35: ANUAL | I35: 45717 | J35: 46082 | L35: =J35-L$5 -> 218
A36: 29 | B36: 13144 | C36: Extintor | D36: 279765 | E36: CO2 | F36: 50 LBS | G36: PTBG | H36: ANUAL | I36: 45717 | J36: 46082 | K36: Prueba Hidrostatica 01/3/2024 HASTA 01/3/2029 | L36: =J36-L$5 -> 218
A37: 30 | B37: PH250 | C37: Extintor | D37: 279714 | E37: CO2 | F37: 50 LBS | G37: PTBG | H37: ANUAL | I37: 45717 | J37: 46082 | K37: Prueba Hidrostatica 01/4/2024 HASTA 01/4/2029 | L37: =J37-L$5 -> 218
A38: 31 | B38: 16210 | C38: Extintor | D38: S/N | E38: PQS | F38: 150 LBS | G38: PTBG | H38: ANUAL | I38: 45717 | J38: 46082 | L38: =J38-L$5 -> 218
A39: 32 | B39: 16211 | C39: Extintor | D39: S/N | E39: PQS | F39: 150 LBS | G39: PTBG | H39: ANUAL | I39: 45717 | J39: 46082 | L39: =J39-L$5 -> 218
A40: 22 | C40: Bombonas CO2 Bg-1 | D40: KF139408 | E40: CO2 | F40: 100 LBS | G40: PTBG | H40: ANUAL | I40: 45231 | J40: 45597 | K40: Prueba Hidrostatica 01/11/2023 HASTA 01/11/2028 | L40: =J40-L$5 -> -267
A41: 23 | C41: Bombonas CO2 Bg-1 | D41: KF139705 | E41: CO2 | F41: 100 LBS | G41: PTBG | H41: ANUAL | I41: 45231 | J41: 45597 | K41: Prueba Hidrostatica 01/11/2023 HASTA 01/11/2028 | L41: =J41-L$5 -> -267
A42: 24 | C42: Bombonas CO2 Bg-1 | D42: KF139685 | E42: CO2 | F42: 100 LBS | G42: PTBG | H42: ANUAL | I42: 45231 | J42: 45597 | K42: Prueba Hidrostatica 01/11/2023 HASTA 01/11/2028 | L42: =J42-L$5 -> -267
A43: 25 | C43: Bombonas CO2 Bg-1 | D43: KF137358 | E43: CO2 | F43: 100 LBS | G43: PTBG | H43: ANUAL | I43: 45231 | J43: 45597 | K43: Prueba Hidrostatica 01/11/2023 HASTA 01/11/2028 | L43: =J43-L$5 -> -267
A44: 26 | C44: Bombonas CO2 Bg-1 | D44: KF139356 | E44: CO2 | F44: 100 LBS | G44: PTBG | H44: ANUAL | I44: 45231 | J44: 45597 | K44: Prueba Hidrostatica 01/11/2023 HASTA 01/11/2028 | L44: =J44-L$5 -> -267
A45: 27 | C45: Bombonas CO2 Bg-1 | D45: KF137847 | E45: CO2 | F45: 100 LBS | G45: PTBG | H45: ANUAL | I45: 45231 | J45: 45597 | K45: Prueba Hidrostatica 01/11/2023 HASTA 01/11/2028 | L45: =J45-L$5 -> -267
...

Sheet Certificado vencido
A2: CONTROL DE LOS EQUIPOS DE MEDICIÓN
B4: DEPARTAMENTO / PROYECTO: | D4: PB ISA 2024-PA-215 "SERVICIO INTEGRAL DE MANTENIMIENTO PREDICTIVO, PREVENTIVO, CORRECTIVO Y OPERACIÓN DE LA PLANTA TERMOELECTRICA BAJO GRANDE"
J5: FECHA DE ACTUALIZACIÓN: | L5: =TODAY() -> 45864 | M5: HOY
A6: ÍTEM | B6: CÓDIGO INTERNO | C6: NOMBRE DEL EQUIPO | D6: SERIAL | E6: MARCA / MODELO | F6: RANGO/ CAPACIDAD | G6: UBICACIÓN | H6: FRECUENCIA DE CALIBRACIÓN, AJUSTE Y/O MANTENIMIENTO | I6: FECHA DE ÚLTIMA CALIBRACIÓN, AJUSTE Y/O MANTENIMIENTO | J6: FECHA DE PRÓXIMA CALIBRACIÓN, AJUSTE Y/O MANTENIMIENTO | K6: OBSERVACIONES
A7: EQUIPOS DE MEDICIÓN (Definir tipo: EQUIPOS MECÁNICOS (MEC), ELÉCTRICOS (ELEC), INSTRUMENTACIÓN (INT), SIA (S) )
A8: 3 | C8: Soporte ajustable para 7 T | D8: _________ | E8: TIPO AJUSTABLE | F8: 7 T | G8: PTBG | H8: ANUAL | I8: 45227 | J8: 45593 | L8: =J8-' por certificar junio'!L$5 -> -271
A9: 4 | C9: Soporte fijo para 7 T | D9: _________ | E9: TIPO FIJO | F9: 7 T | G9: PTBG | H9: ANUAL | I9: 45227 | J9: 45593 | L9: =J9-' por certificar junio'!L$5 -> -271
A10: 5 | C10: Grua Monoriel | D10: 189083189 | E10: CHESTER / ZEPHYR | F10: 10.000 KGS | G10: PTBG | H10: ANUAL | I10: 45378 | J10: 45743 | L10: =J10-' por certificar junio'!L$5 -> -121
A11: 6 | C11: Guante Dielectrico , CLASE 3 TIPO 1 de 12" | D11: 5332860 / 5332859 | E11: SALISBURY/ PRODUSCA D120/ ILP14 | F11: 26500 V AC | G11: PTBG | H11: SEMESTRAL | I11: 45613 | J11: 45794 | K11: CORPOELEC | L11: =J11-' por certificar junio'!L$5 -> -70
A12: 7 | L12: =J12-' por certificar junio'!L$5 -> -45864
A13: 8 | L13: =J13-' por certificar junio'!L$5 -> -45864
A14: 9 | L14: =J14-' por certificar junio'!L$5 -> -45864
A15: 10 | L15: =J15-' por certificar junio'!L$5 -> -45864
A16: 11 | L16: =J16-' por certificar junio'!L$5 -> -45864
A17: 12 | L17: =J17-' por certificar junio'!L$5 -> -45864
A18: 13 | L18: =J18-' por certificar junio'!L$5 -> -45864
A19: 13
A20: 14
A21: 15
A22: 16
A23: 17
A24: 18
A25: 19
A26: 20
A27: 21
A28: 22
A29: 23 | L29: =J29-L$5 -> -45864
A30: 24 | L30: =J30-L$5 -> -45864
A31: 25 | L31: =J31-L$5 -> -45864
A32: 26 | L32: =J32-L$5 -> -45864
A33: 27 | L33: =J33-L$5 -> -45864
A34: 28 | L34: =J34-L$5 -> -45864
A35: 29 | L35: =J35-L$5 -> -45864
A36: 30 | L36: =J36-L$5 -> -45864
A37: 31 | L37: =J37-L$5 -> -45864
A38: 32 | L38: =J38-L$5 -> -45864
A39: 33 | L39: =J39-L$5 -> -45864
A40: 34 | L40: =J40-L$5 -> -45864
... A52: 46 | L52: =J52-L$5 -> -45864
L53: =J53-L$5 -> -45864
...

Sheet  por certificar junio
A2: CONTROL DE LOS EQUIPOS DE MEDICIÓN
B4: DEPARTAMENTO / PROYECTO: | D4: PB ISA 2024-PA-215 "SERVICIO INTEGRAL DE MANTENIMIENTO PREDICTIVO, PREVENTIVO, CORRECTIVO Y OPERACIÓN DE LA PLANTA TERMOELECTRICA BAJO GRANDE"
J5: FECHA DE ACTUALIZACIÓN: | L5: =TODAY() -> 45864 | M5: HOY
A6: ÍTEM | B6: CÓDIGO INTERNO | C6: NOMBRE DEL EQUIPO | D6: SERIAL | E6: MARCA / MODELO | F6: RANGO/ CAPACIDAD | G6: UBICACIÓN | H6: FRECUENCIA DE CALIBRACIÓN, AJUSTE Y/O MANTENIMIENTO | I6: FECHA DE ÚLTIMA CALIBRACIÓN, AJUSTE Y/O MANTENIMIENTO | J6: FECHA DE PRÓXIMA CALIBRACIÓN, AJUSTE Y/O MANTENIMIENTO | K6: OBSERVACIONES
A7: EQUIPOS DE MEDICIÓN (Definir tipo: EQUIPOS MECÁNICOS (MEC), ELÉCTRICOS (ELEC), INSTRUMENTACIÓN (INT), SIA (S) )
A8: Junio
A9: 20 | C9: SF6-Gas super liquefaction system | D9: SLR1032 | E9: WOOSUNG/ SLR-600-06 | F9: CAP.LIQ.600L | G9: PTBG | H9: SEMESTRAL | I9: 45643 | J9: 45825 | L9: =J9-L$5 -> -39
L11: =J11-L$5 -> -45864
A17: 34 | L17: =J17-L$5 -> -45864
A18: 35 | L18: =J18-L$5 -> -45864
A19: 36 | L19: =J19-L$5 -> -45864
A20: 37 | L20: =J20-L$5 -> -45864
A21: 38 | L21: =J21-L$5 -> -45864
A22: 39 | L22: =J22-L$5 -> -45864
A23: 40 | L23: =J23-L$5 -> -45864
A24: 41 | L24: =J24-L$5 -> -45864
A25: 42 | L25: =J25-L$5 -> -45864
A26: 43 | L26: =J26-L$5 -> -45864
A27: 44 | L27: =J27-L$5 -> -45864
A28: 45 | L28: =J28-L$5 -> -45864
A29: 46 | L29: =J29-L$5 -> -45864
L30: =J30-L$5 -> -45864
L31: =J31-L$5 -> -45864
L32: =J32-L$5 -> -45864
A33: 50 | L33: =J33-L$5 -> -45864
A34: 51 | L34: =J34-L$5 -> -45864
L35: =J35-L$5 -> -45864
L36: =J36-L$5 -> -45864
L37: =J37-L$5 -> -45864
L38: =J38-L$5 -> -45864
L39: =J39-L$5 -> -45864
L40: =J40-L$5 -> -45864
L41: =J41-L$5 -> -45864
L42: =J42-L$5 -> -45864
L43: =J43-L$5 -> -45864
L44: =J44-L$5 -> -45864
A45: 62 | L45: =J45-L$5 -> -45864
A46: 63 | L46: =J46-L$5 -> -45864
L47: =J47-L$5 -> -45864
L48: =J48-L$5 -> -45864
...
